[2024-06-24T11:50:59.128+0700] {local_task_job_runner.py:120} INFO - ::group::Pre task execution logs
[2024-06-24T11:50:59.146+0700] {taskinstance.py:2076} INFO - Dependencies all met for dep_context=non-requeueable deps ti=<TaskInstance: user_processing.process_user scheduled__2024-06-23T00:00:00+00:00 [queued]>
[2024-06-24T11:50:59.155+0700] {taskinstance.py:2076} INFO - Dependencies all met for dep_context=requeueable deps ti=<TaskInstance: user_processing.process_user scheduled__2024-06-23T00:00:00+00:00 [queued]>
[2024-06-24T11:50:59.156+0700] {taskinstance.py:2306} INFO - Starting attempt 1 of 1
[2024-06-24T11:50:59.170+0700] {taskinstance.py:2330} INFO - Executing <Task(PythonOperator): process_user> on 2024-06-23 00:00:00+00:00
[2024-06-24T11:50:59.177+0700] {standard_task_runner.py:63} INFO - Started process 30894 to run task
[2024-06-24T11:50:59.185+0700] {standard_task_runner.py:90} INFO - Running: ['***', 'tasks', 'run', 'user_processing', 'process_user', 'scheduled__2024-06-23T00:00:00+00:00', '--job-id', '13', '--raw', '--subdir', 'DAGS_FOLDER/user_processing.py', '--cfg-path', '/tmp/tmpnke25ac7']
[2024-06-24T11:50:59.186+0700] {standard_task_runner.py:91} INFO - Job 13: Subtask process_user
[2024-06-24T11:50:59.280+0700] {task_command.py:426} INFO - Running <TaskInstance: user_processing.process_user scheduled__2024-06-23T00:00:00+00:00 [running]> on host daniel
[2024-06-24T11:50:59.389+0700] {taskinstance.py:2648} INFO - Exporting env vars: AIRFLOW_CTX_DAG_OWNER='***' AIRFLOW_CTX_DAG_ID='user_processing' AIRFLOW_CTX_TASK_ID='process_user' AIRFLOW_CTX_EXECUTION_DATE='2024-06-23T00:00:00+00:00' AIRFLOW_CTX_TRY_NUMBER='1' AIRFLOW_CTX_DAG_RUN_ID='scheduled__2024-06-23T00:00:00+00:00'
[2024-06-24T11:50:59.394+0700] {taskinstance.py:430} INFO - ::endgroup::
[2024-06-24T11:50:59.411+0700] {taskinstance.py:441} INFO - ::group::Post task execution logs
[2024-06-24T11:50:59.412+0700] {taskinstance.py:2905} ERROR - Task failed with exception
Traceback (most recent call last):
  File "/home/daniel/airflow/venv/lib/python3.10/site-packages/airflow/models/taskinstance.py", line 465, in _execute_task
    result = _execute_callable(context=context, **execute_callable_kwargs)
  File "/home/daniel/airflow/venv/lib/python3.10/site-packages/airflow/models/taskinstance.py", line 432, in _execute_callable
    return execute_callable(context=context, **execute_callable_kwargs)
  File "/home/daniel/airflow/venv/lib/python3.10/site-packages/airflow/models/baseoperator.py", line 401, in wrapper
    return func(self, *args, **kwargs)
  File "/home/daniel/airflow/venv/lib/python3.10/site-packages/airflow/operators/python.py", line 235, in execute
    return_value = self.execute_callable()
  File "/home/daniel/airflow/venv/lib/python3.10/site-packages/airflow/operators/python.py", line 252, in execute_callable
    return self.python_callable(*self.op_args, **self.op_kwargs)
  File "/home/daniel/airflow/dags/user_processing.py", line 15, in _process_user
    user = user['result'][0]
TypeError: 'NoneType' object is not subscriptable
[2024-06-24T11:50:59.425+0700] {taskinstance.py:1206} INFO - Marking task as FAILED. dag_id=user_processing, task_id=process_user, run_id=scheduled__2024-06-23T00:00:00+00:00, execution_date=20240623T000000, start_date=20240624T045059, end_date=20240624T045059
[2024-06-24T11:50:59.435+0700] {standard_task_runner.py:110} ERROR - Failed to execute job 13 for task process_user ('NoneType' object is not subscriptable; 30894)
[2024-06-24T11:50:59.479+0700] {local_task_job_runner.py:240} INFO - Task exited with return code 1
[2024-06-24T11:50:59.499+0700] {taskinstance.py:3503} INFO - 0 downstream tasks scheduled from follow-on schedule check
[2024-06-24T11:50:59.501+0700] {local_task_job_runner.py:222} INFO - ::endgroup::
